Workbook

Sheet CAPA
A1: FORCE · GESTÃO DE ATIVOS E OPERAÇÕES
A2: Painel de Controle · Passaporte Técnico do Ativo
A4: TOTAL DE ATIVOS | C4: ATIVOS CRÍTICOS (C+D) | E4: ALERTAS ABERTOS | G4: INSPEÇÕES REGISTRADAS
A5: =COUNTA(ATIVO_PAI!A2:A1000) -> 5 | C5: =COUNTIF(ATIVO_PAI!G2:G1000,"C")+COUNTIF(ATIVO_PAI!G2:G1000,"D") -> 2 | E5: =COUNTIF(OCORRENCIAS!F2:F1000,"Aberta") -> 11 | G5: =COUNTA(INSPECOES!A2:A1000) -> 6
A7: ATALHOS RÁPIDOS
A8: 🪪 Abrir Passaporte | C8: 📊 Ver Resumo | E8: 📚 Ver Legenda | G8: 📅 Ver Inspeções
A10: ÚLTIMAS INSPEÇÕES REGISTRADAS
A11: Insp_ID | B11: Data | C11: Ativo | D11: Inspetor | E11: Antes | F11: Depois | G11: Km | H11: Resumo
A12: =IFERROR(INSPECOES!A1,"") -> Insp_ID | B12: =IFERROR(INSPECOES!C1,"") -> Data | C12: =IFERROR(INSPECOES!B1,"") -> Asset_ID | D12: =IFERROR(INSPECOES!D1,"") -> Inspecionado_Por | E12: =IFERROR(INSPECOES!E1,"") -> Class_Antes | F12: =IFERROR(INSPECOES!F1,"") -> Class_Depois | G12: =IFERROR(INSPECOES!G1,"") -> Km_Horimetro | H12: =IFERROR(INSPECOES!H1,"") -> Resumo
A13: =IFERROR(INSPECOES!A2,"") -> INS-006 | B13: =IFERROR(INSPECOES!C2,"") -> 2026-09-26 | C13: =IFERROR(INSPECOES!B2,"") -> ATV-004 | D13: =IFERROR(INSPECOES!D2,"") -> Kaká | E13: =IFERROR(INSPECOES!E2,"") -> C | F13: =IFERROR(INSPECOES!F2,"") -> D | G13: =IFERROR(INSPECOES!G2,"") -> 4200 | H13: =IFERROR(INSPECOES!H2,"") -> Motor travou; bloqueio técnico
A14: =IFERROR(INSPECOES!A3,"") -> INS-005 | B14: =IFERROR(INSPECOES!C3,"") -> 2026-09-27 | C14: =IFERROR(INSPECOES!B3,"") -> ATV-003 | D14: =IFERROR(INSPECOES!D3,"") -> Kaká | E14: =IFERROR(INSPECOES!E3,"") -> B | F14: =IFERROR(INSPECOES!F3,"") -> C | G14: =IFERROR(INSPECOES!G3,"") -> 98750 | H14: =IFERROR(INSPECOES!H3,"") -> Freios e injeção degradaram
A15: =IFERROR(INSPECOES!A4,"") -> INS-004 | B15: =IFERROR(INSPECOES!C4,"") -> 2026-09-25 | C15: =IFERROR(INSPECOES!B4,"") -> ATV-005 | D15: =IFERROR(INSPECOES!D4,"") -> Kaká | E15: =IFERROR(INSPECOES!E4,"") -> A | F15: =IFERROR(INSPECOES!F4,"") -> A | G15: =IFERROR(INSPECOES!G4,"") -> 18400 | H15: =IFERROR(INSPECOES!H4,"") -> Sem alteração
A16: =IFERROR(INSPECOES!A5,"") -> INS-003 | B16: =IFERROR(INSPECOES!C5,"") -> 2026-09-28 | C16: =IFERROR(INSPECOES!B5,"") -> ATV-002 | D16: =IFERROR(INSPECOES!D5,"") -> Kaká | E16: =IFERROR(INSPECOES!E5,"") -> A | F16: =IFERROR(INSPECOES!F5,"") -> A | G16: =IFERROR(INSPECOES!G5,"") -> 82300 | H16: =IFERROR(INSPECOES!H5,"") -> Sem alteração
A18: COMO USAR ESTA PLANILHA
A19: 1. Selecione um ativo no dropdown do PASSAPORTE para ver a ficha completa.
A20: 2. Quando o Kaká faz uma inspeção, registre em INSPECOES e atualize ATIVO_PAI.
A21: 3. Toda mudança relevante (subativo, pneu, ocorrência) gera linha em EVENTOS.
A22: 4. O RESUMO mostra a situação geral e as pendências. Use a aba ALERTAS.
A23: 5. Classificações, status e tipos estão explicados na aba LEGENDA.
A24: 6. Nunca apague linhas de INSPECOES e EVENTOS. Histórico é sempre adicionado.

Sheet PASSAPORTE
A1: PASSAPORTE TÉCNICO DO ATIVO
A2: FORCE · Gestão de Ativos e Operações · Documento de Controle Patrimonial
A4: SELECIONE O ATIVO | B4: ATV-003 | D4: STATUS GERAL | E4: =IF(OR(VLOOKUP($B$4,ATIVO_PAI!A:H,7,0)="D",COUNTIFS(SUBATIVOS!B:B,$B$4,SUBATIVOS!D:D,"Inoperante")>0,COUNTIFS(PNEUS!B:B,$B$4,PNEUS!G:G,"Condenado")>0),"Crítico",IF(OR(VLOOKUP($B$4,ATIVO_PAI!A:H,7,0)="C",COUNTIFS(OCORRENCIAS!B:B,$B$4,OCORRENCIAS!F:F,"Aberta")>0,COUNTIFS(SUBATIVOS!B:B,$B$4,SUBATIVOS!D:D,"Degradado")>0),"Atenção","OK")) -> Crítico
A6: 1. IDENTIFICAÇÃO DO ATIVO
A7: Asset ID | B7: =IFERROR(VLOOKUP($B$4,ATIVO_PAI!A:H,1,0),"") -> ATV-003
A8: Placa | B8: =IFERROR(VLOOKUP($B$4,ATIVO_PAI!A:H,2,0),"") -> GHI7J89
A9: Tipo | B9: =IFERROR(VLOOKUP($B$4,ATIVO_PAI!A:H,3,0),"") -> Van
A10: Próprio/Locado | B10: =IFERROR(VLOOKUP($B$4,ATIVO_PAI!A:H,4,0),"") -> Locado
A11: Locador | B11: =IFERROR(VLOOKUP($B$4,ATIVO_PAI!A:H,5,0),"") -> Locadora Y
A12: Km/Horímetro | B12: =IFERROR(VLOOKUP($B$4,ATIVO_PAI!A:H,6,0),"") -> 98750
A13: Classificação | B13: =IFERROR(VLOOKUP($B$4,ATIVO_PAI!A:H,7,0),"") -> C
A14: Data da inspeção | B14: =IFERROR(VLOOKUP($B$4,ATIVO_PAI!A:H,8,0),"") -> 2026-09-27
A16: 2. HISTÓRICO DE INSPEÇÕES (5 mais recentes)
A17: Insp_ID | B17: Data | C17: Inspetor | D17: Class_Antes | E17: Class_Depois | F17: Km
A18: =IFERROR(INDEX(INSPECOES!A:A,MATCH(1,INSPECOES!$I:$I,0)),"") -> INS-005 | B18: =IFERROR(INDEX(INSPECOES!C:C,MATCH(1,INSPECOES!$I:$I,0)),"") -> 2026-09-27 | C18: =IFERROR(INDEX(INSPECOES!D:D,MATCH(1,INSPECOES!$I:$I,0)),"") -> Kaká | D18: =IFERROR(INDEX(INSPECOES!E:E,MATCH(1,INSPECOES!$I:$I,0)),"") -> B | E18: =IFERROR(INDEX(INSPECOES!F:F,MATCH(1,INSPECOES!$I:$I,0)),"") -> C | F18: =IFERROR(INDEX(INSPECOES!G:G,MATCH(1,INSPECOES!$I:$I,0)),"") -> 98750
A19: =IFERROR(INDEX(INSPECOES!A:A,MATCH(2,INSPECOES!$I:$I,0)),"") | B19: =IFERROR(INDEX(INSPECOES!C:C,MATCH(2,INSPECOES!$I:$I,0)),"") | C19: =IFERROR(INDEX(INSPECOES!D:D,MATCH(2,INSPECOES!$I:$I,0)),"") | D19: =IFERROR(INDEX(INSPECOES!E:E,MATCH(2,INSPECOES!$I:$I,0)),"") | E19: =IFERROR(INDEX(INSPECOES!F:F,MATCH(2,INSPECOES!$I:$I,0)),"") | F19: =IFERROR(INDEX(INSPECOES!G:G,MATCH(2,INSPECOES!$I:$I,0)),"")
A20: =IFERROR(INDEX(INSPECOES!A:A,MATCH(3,INSPECOES!$I:$I,0)),"") | B20: =IFERROR(INDEX(INSPECOES!C:C,MATCH(3,INSPECOES!$I:$I,0)),"") | C20: =IFERROR(INDEX(INSPECOES!D:D,MATCH(3,INSPECOES!$I:$I,0)),"") | D20: =IFERROR(INDEX(INSPECOES!E:E,MATCH(3,INSPECOES!$I:$I,0)),"") | E20: =IFERROR(INDEX(INSPECOES!F:F,MATCH(3,INSPECOES!$I:$I,0)),"") | F20: =IFERROR(INDEX(INSPECOES!G:G,MATCH(3,INSPECOES!$I:$I,0)),"")
A21: =IFERROR(INDEX(INSPECOES!A:A,MATCH(4,INSPECOES!$I:$I,0)),"") | B21: =IFERROR(INDEX(INSPECOES!C:C,MATCH(4,INSPECOES!$I:$I,0)),"") | C21: =IFERROR(INDEX(INSPECOES!D:D,MATCH(4,INSPECOES!$I:$I,0)),"") | D21: =IFERROR(INDEX(INSPECOES!E:E,MATCH(4,INSPECOES!$I:$I,0)),"") | E21: =IFERROR(INDEX(INSPECOES!F:F,MATCH(4,INSPECOES!$I:$I,0)),"") | F21: =IFERROR(INDEX(INSPECOES!G:G,MATCH(4,INSPECOES!$I:$I,0)),"")
A22: =IFERROR(INDEX(INSPECOES!A:A,MATCH(5,INSPECOES!$I:$I,0)),"") | B22: =IFERROR(INDEX(INSPECOES!C:C,MATCH(5,INSPECOES!$I:$I,0)),"") | C22: =IFERROR(INDEX(INSPECOES!D:D,MATCH(5,INSPECOES!$I:$I,0)),"") | D22: =IFERROR(INDEX(INSPECOES!E:E,MATCH(5,INSPECOES!$I:$I,0)),"") | E22: =IFERROR(INDEX(INSPECOES!F:F,MATCH(5,INSPECOES!$I:$I,0)),"") | F22: =IFERROR(INDEX(INSPECOES!G:G,MATCH(5,INSPECOES!$I:$I,0)),"")
A24: 3. ÚLTIMOS EVENTOS (5 mais recentes)
A25: Evento_ID | B25: Data | C25: Tipo | D25: Descrição | E25: Antes | F25: Depois
A26: =IFERROR(INDEX(EVENTOS!A:A,MATCH(1,EVENTOS!$J:$J,0)),"") | B26: =IFERROR(INDEX(EVENTOS!B:B,MATCH(1,EVENTOS!$J:$J,0)),"") | C26: =IFERROR(INDEX(EVENTOS!D:D,MATCH(1,EVENTOS!$J:$J,0)),"") | D26: =IFERROR(INDEX(EVENTOS!F:F,MATCH(1,EVENTOS!$J:$J,0)),"") | E26: =IFERROR(INDEX(EVENTOS!G:G,MATCH(1,EVENTOS!$J:$J,0)),"") | F26: =IFERROR(INDEX(EVENTOS!H:H,MATCH(1,EVENTOS!$J:$J,0)),"")
A27: =IFERROR(INDEX(EVENTOS!A:A,MATCH(2,EVENTOS!$J:$J,0)),"") | B27: =IFERROR(INDEX(EVENTOS!B:B,MATCH(2,EVENTOS!$J:$J,0)),"") | C27: =IFERROR(INDEX(EVENTOS!D:D,MATCH(2,EVENTOS!$J:$J,0)),"") | D27: =IFERROR(INDEX(EVENTOS!F:F,MATCH(2,EVENTOS!$J:$J,0)),"") | E27: =IFERROR(INDEX(EVENTOS!G:G,MATCH(2,EVENTOS!$J:$J,0)),"") | F27: =IFERROR(INDEX(EVENTOS!H:H,MATCH(2,EVENTOS!$J:$J,0)),"")
A28: =IFERROR(INDEX(EVENTOS!A:A,MATCH(3,EVENTOS!$J:$J,0)),"") | B28: =IFERROR(INDEX(EVENTOS!B:B,MATCH(3,EVENTOS!$J:$J,0)),"") | C28: =IFERROR(INDEX(EVENTOS!D:D,MATCH(3,EVENTOS!$J:$J,0)),"") | D28: =IFERROR(INDEX(EVENTOS!F:F,MATCH(3,EVENTOS!$J:$J,0)),"") | E28: =IFERROR(INDEX(EVENTOS!G:G,MATCH(3,EVENTOS!$J:$J,0)),"") | F28: =IFERROR(INDEX(EVENTOS!H:H,MATCH(3,EVENTOS!$J:$J,0)),"")
A29: =IFERROR(INDEX(EVENTOS!A:A,MATCH(4,EVENTOS!$J:$J,0)),"") | B29: =IFERROR(INDEX(EVENTOS!B:B,MATCH(4,EVENTOS!$J:$J,0)),"") | C29: =IFERROR(INDEX(EVENTOS!D:D,MATCH(4,EVENTOS!$J:$J,0)),"") | D29: =IFERROR(INDEX(EVENTOS!F:F,MATCH(4,EVENTOS!$J:$J,0)),"") | E29: =IFERROR(INDEX(EVENTOS!G:G,MATCH(4,EVENTOS!$J:$J,0)),"") | F29: =IFERROR(INDEX(EVENTOS!H:H,MATCH(4,EVENTOS!$J:$J,0)),"")
A30: =IFERROR(INDEX(EVENTOS!A:A,MATCH(5,EVENTOS!$J:$J,0)),"") | B30: =IFERROR(INDEX(EVENTOS!B:B,MATCH(5,EVENTOS!$J:$J,0)),"") | C30: =IFERROR(INDEX(EVENTOS!D:D,MATCH(5,EVENTOS!$J:$J,0)),"") | D30: =IFERROR(INDEX(EVENTOS!F:F,MATCH(5,EVENTOS!$J:$J,0)),"") | E30: =IFERROR(INDEX(EVENTOS!G:G,MATCH(5,EVENTOS!$J:$J,0)),"") | F30: =IFERROR(INDEX(EVENTOS!H:H,MATCH(5,EVENTOS!$J:$J,0)),"")
A32: 4. SUBATIVOS
A33: Sub_ID | B33: Nome | C33: Estado | D33: Classificação | E33: Ação | F33: Prioridade
A34: =IFERROR(INDEX(SUBATIVOS!A:A,MATCH(1,SUBATIVOS!$H:$H,0)),"") -> SUB-007 | B34: =IFERROR(INDEX(SUBATIVOS!C:C,MATCH(1,SUBATIVOS!$H:$H,0)),"") -> Motor | C34: =IFERROR(INDEX(SUBATIVOS!D:D,MATCH(1,SUBATIVOS!$H:$H,0)),"") -> Degradado | D34: =IFERROR(INDEX(SUBATIVOS!E:E,MATCH(1,SUBATIVOS!$H:$H,0)),"") -> B | E34: =IFERROR(INDEX(SUBATIVOS!F:F,MATCH(1,SUBATIVOS!$H:$H,0)),"") -> Revisar injeção | F34: =IFERROR(INDEX(SUBATIVOS!G:G,MATCH(1,SUBATIVOS!$H:$H,0)),"") -> Média
A35: =IFERROR(INDEX(SUBATIVOS!A:A,MATCH(2,SUBATIVOS!$H:$H,0)),"") -> SUB-008 | B35: =IFERROR(INDEX(SUBATIVOS!C:C,MATCH(2,SUBATIVOS!$H:$H,0)),"") -> Freios | C35: =IFERROR(INDEX(SUBATIVOS!D:D,MATCH(2,SUBATIVOS!$H:$H,0)),"") -> Degradado | D35: =IFERROR(INDEX(SUBATIVOS!E:E,MATCH(2,SUBATIVOS!$H:$H,0)),"") -> C | E35: =IFERROR(INDEX(SUBATIVOS!F:F,MATCH(2,SUBATIVOS!$H:$H,0)),"") -> Trocar discos | F35: =IFERROR(INDEX(SUBATIVOS!G:G,MATCH(2,SUBATIVOS!$H:$H,0)),"") -> Alta
A36: =IFERROR(INDEX(SUBATIVOS!A:A,MATCH(3,SUBATIVOS!$H:$H,0)),"") -> SUB-009 | B36: =IFERROR(INDEX(SUBATIVOS!C:C,MATCH(3,SUBATIVOS!$H:$H,0)),"") -> Elétrica | C36: =IFERROR(INDEX(SUBATIVOS!D:D,MATCH(3,SUBATIVOS!$H:$H,0)),"") -> Funcional | D36: =IFERROR(INDEX(SUBATIVOS!E:E,MATCH(3,SUBATIVOS!$H:$H,0)),"") -> A | E36: =IFERROR(INDEX(SUBATIVOS!F:F,MATCH(3,SUBATIVOS!$H:$H,0)),"") -> Nenhuma | F36: =IFERROR(INDEX(SUBATIVOS!G:G,MATCH(3,SUBATIVOS!$H:$H,0)),"") -> Baixa
A37: =IFERROR(INDEX(SUBATIVOS!A:A,MATCH(4,SUBATIVOS!$H:$H,0)),"") | B37: =IFERROR(INDEX(SUBATIVOS!C:C,MATCH(4,SUBATIVOS!$H:$H,0)),"") | C37: =IFERROR(INDEX(SUBATIVOS!D:D,MATCH(4,SUBATIVOS!$H:$H,0)),"") | D37: =IFERROR(INDEX(SUBATIVOS!E:E,MATCH(4,SUBATIVOS!$H:$H,0)),"") | E37: =IFERROR(INDEX(SUBATIVOS!F:F,MATCH(4,SUBATIVOS!$H:$H,0)),"") | F37: =IFERROR(INDEX(SUBATIVOS!G:G,MATCH(4,SUBATIVOS!$H:$H,0)),"")
A38: =IFERROR(INDEX(SUBATIVOS!A:A,MATCH(5,SUBATIVOS!$H:$H,0)),"") | B38: =IFERROR(INDEX(SUBATIVOS!C:C,MATCH(5,SUBATIVOS!$H:$H,0)),"") | C38: =IFERROR(INDEX(SUBATIVOS!D:D,MATCH(5,SUBATIVOS!$H:$H,0)),"") | D38: =IFERROR(INDEX(SUBATIVOS!E:E,MATCH(5,SUBATIVOS!$H:$H,0)),"") | E38: =IFERROR(INDEX(SUBATIVOS!F:F,MATCH(5,SUBATIVOS!$H:$H,0)),"") | F38: =IFERROR(INDEX(SUBATIVOS!G:G,MATCH(5,SUBATIVOS!$H:$H,0)),"")
A39: =IFERROR(INDEX(SUBATIVOS!A:A,MATCH(6,SUBATIVOS!$H:$H,0)),"") | B39: =IFERROR(INDEX(SUBATIVOS!C:C,MATCH(6,SUBATIVOS!$H:$H,0)),"") | C39: =IFERROR(INDEX(SUBATIVOS!D:D,MATCH(6,SUBATIVOS!$H:$H,0)),"") | D39: =IFERROR(INDEX(SUBATIVOS!E:E,MATCH(6,SUBATIVOS!$H:$H,0)),"") | E39: =IFERROR(INDEX(SUBATIVOS!F:F,MATCH(6,SUBATIVOS!$H:$H,0)),"") | F39: =IFERROR(INDEX(SUBATIVOS!G:G,MATCH(6,SUBATIVOS!$H:$H,0)),"")
A40: =IFERROR(INDEX(SUBATIVOS!A:A,MATCH(7,SUBATIVOS!$H:$H,0)),"") | B40: =IFERROR(INDEX(SUBATIVOS!C:C,MATCH(7,SUBATIVOS!$H:$H,0)),"") | C40: =IFERROR(INDEX(SUBATIVOS!D:D,MATCH(7,SUBATIVOS!$H:$H,0)),"") | D40: =IFERROR(INDEX(SUBATIVOS!E:E,MATCH(7,SUBATIVOS!$H:$H,0)),"") | E40: =IFERROR(INDEX(SUBATIVOS!F:F,MATCH(7,SUBATIVOS!$H:$H,0)),"") | F40: =IFERROR(INDEX(SUBATIVOS!G:G,MATCH(7,SUBATIVOS!$H:$H,0)),"")
A41: =IFERROR(INDEX(SUBATIVOS!A:A,MATCH(8,SUBATIVOS!$H:$H,0)),"") | B41: =IFERROR(INDEX(SUBATIVOS!C:C,MATCH(8,SUBATIVOS!$H:$H,0)),"") | C41: =IFERROR(INDEX(SUBATIVOS!D:D,MATCH(8,SUBATIVOS!$H:$H,0)),"") | D41: =IFERROR(INDEX(SUBATIVOS!E:E,MATCH(8,SUBATIVOS!$H:$H,0)),"") | E41: =IFERROR(INDEX(SUBATIVOS!F:F,MATCH(8,SUBATIVOS!$H:$H,0)),"") | F41: =IFERROR(INDEX(SUBATIVOS!G:G,MATCH(8,SUBATIVOS!$H:$H,0)),"")
A42: =IFERROR(INDEX(SUBATIVOS!A:A,MATCH(9,SUBATIVOS!$H:$H,0)),"") | B42: =IFERROR(INDEX(SUBATIVOS!C:C,MATCH(9,SUBATIVOS!$H:$H,0)),"") | C42: =IFERROR(INDEX(SUBATIVOS!D:D,MATCH(9,SUBATIVOS!$H:$H,0)),"") | D42: =IFERROR(INDEX(SUBATIVOS!E:E,MATCH(9,SUBATIVOS!$H:$H,0)),"") | E42: =IFERROR(INDEX(SUBATIVOS!F:F,MATCH(9,SUBATIVOS!$H:$H,0)),"") | F42: =IFERROR(INDEX(SUBATIVOS!G:G,MATCH(9,SUBATIVOS!$H:$H,0)),"")
A43: =IFERROR(INDEX(SUBATIVOS!A:A,MATCH(10,SUBATIVOS!$H:$H,0)),"") | B43: =IFERROR(INDEX(SUBATIVOS!C:C,MATCH(10,SUBATIVOS!$H:$H,0)),"") | C43: =IFERROR(INDEX(SUBATIVOS!D:D,MATCH(10,SUBATIVOS!$H:$H,0)),"") | D43: =IFERROR(INDEX(SUBATIVOS!E:E,MATCH(10,SUBATIVOS!$H:$H,0)),"") | E43: =IFERROR(INDEX(SUBATIVOS!F:F,MATCH(10,SUBATIVOS!$H:$H,0)),"") | F43: =IFERROR(INDEX(SUBATIVOS!G:G,MATCH(10,SUBATIVOS!$H:$H,0)),"")
A45: 5. PNEUS
A46: Pneu_ID | B46: Posição | C46: Marca | D46: Medida | E46: Sulco | F46: Status
...

Sheet RESUMO
A1: RESUMO GERAL
A2: Indicador | B2: Valor
A3: Total de ativos | B3: =COUNTA(ATIVO_PAI!A2:A1000) -> 5
A4: Ativos classe A | B4: =COUNTIF(ATIVO_PAI!G2:G1000,"A") -> 2
A5: Ativos classe B | B5: =COUNTIF(ATIVO_PAI!G2:G1000,"B") -> 1
A6: Ativos classe C | B6: =COUNTIF(ATIVO_PAI!G2:G1000,"C") -> 1
A7: Ativos classe D | B7: =COUNTIF(ATIVO_PAI!G2:G1000,"D") -> 1
A8: Ocorrências abertas | B8: =COUNTIF(OCORRENCIAS!F2:F1000,"Aberta") -> 11
A9: Subativos degradados | B9: =COUNTIF(SUBATIVOS!D2:D1000,"Degradado") -> 4
A10: Subativos inoperantes | B10: =COUNTIF(SUBATIVOS!D2:D1000,"Inoperante") -> 2
A11: Pneus condenados | B11: =COUNTIF(PNEUS!G2:G1000,"Condenado") -> 3
A12: Inspeções registradas | B12: =COUNTA(INSPECOES!A2:A1000) -> 6
A13: Eventos registrados | B13: =COUNTA(EVENTOS!A2:A1000) -> 8
A15: PENDÊNCIAS POR ATIVO
A16: Asset_ID | B16: Placa | C16: Classificação | D16: Ocor. Abertas | E16: Subat. Degradados | F16: Pneus Condenados | G16: Status Geral
A17: ATV-001 | B17: =VLOOKUP(A17,ATIVO_PAI!A:H,2,0) -> ABC1D23 | C17: =VLOOKUP(A17,ATIVO_PAI!A:H,7,0) -> B | D17: =COUNTIFS(OCORRENCIAS!B:B,A17,OCORRENCIAS!F:F,"Aberta") -> 3 | E17: =COUNTIFS(SUBATIVOS!B:B,A17,SUBATIVOS!D:D,"Degradado") -> 1 | F17: =COUNTIFS(PNEUS!B:B,A17,PNEUS!G:G,"Condenado") -> 0 | G17: =IF(OR(C17="D",COUNTIFS(SUBATIVOS!B:B,A17,SUBATIVOS!D:D,"Inoperante")>0,F17>0),"Crítico",IF(OR(C17="C",D17>0,E17>0),"Atenção","OK")) -> Atenção
A18: ATV-002 | B18: =VLOOKUP(A18,ATIVO_PAI!A:H,2,0) -> DEF4G56 | C18: =VLOOKUP(A18,ATIVO_PAI!A:H,7,0) -> A | D18: =COUNTIFS(OCORRENCIAS!B:B,A18,OCORRENCIAS!F:F,"Aberta") -> 0 | E18: =COUNTIFS(SUBATIVOS!B:B,A18,SUBATIVOS!D:D,"Degradado") -> 0 | F18: =COUNTIFS(PNEUS!B:B,A18,PNEUS!G:G,"Condenado") -> 0 | G18: =IF(OR(C18="D",COUNTIFS(SUBATIVOS!B:B,A18,SUBATIVOS!D:D,"Inoperante")>0,F18>0),"Crítico",IF(OR(C18="C",D18>0,E18>0),"Atenção","OK")) -> OK
A19: ATV-003 | B19: =VLOOKUP(A19,ATIVO_PAI!A:H,2,0) -> GHI7J89 | C19: =VLOOKUP(A19,ATIVO_PAI!A:H,7,0) -> C | D19: =COUNTIFS(OCORRENCIAS!B:B,A19,OCORRENCIAS!F:F,"Aberta") -> 4 | E19: =COUNTIFS(SUBATIVOS!B:B,A19,SUBATIVOS!D:D,"Degradado") -> 2 | F19: =COUNTIFS(PNEUS!B:B,A19,PNEUS!G:G,"Condenado") -> 1 | G19: =IF(OR(C19="D",COUNTIFS(SUBATIVOS!B:B,A19,SUBATIVOS!D:D,"Inoperante")>0,F19>0),"Crítico",IF(OR(C19="C",D19>0,E19>0),"Atenção","OK")) -> Crítico
A20: ATV-004 | B20: =VLOOKUP(A20,ATIVO_PAI!A:H,2,0) -> JKL0M12 | C20: =VLOOKUP(A20,ATIVO_PAI!A:H,7,0) -> D | D20: =COUNTIFS(OCORRENCIAS!B:B,A20,OCORRENCIAS!F:F,"Aberta") -> 3 | E20: =COUNTIFS(SUBATIVOS!B:B,A20,SUBATIVOS!D:D,"Degradado") -> 1 | F20: =COUNTIFS(PNEUS!B:B,A20,PNEUS!G:G,"Condenado") -> 2 | G20: =IF(OR(C20="D",COUNTIFS(SUBATIVOS!B:B,A20,SUBATIVOS!D:D,"Inoperante")>0,F20>0),"Crítico",IF(OR(C20="C",D20>0,E20>0),"Atenção","OK")) -> Crítico
A21: ATV-005 | B21: =VLOOKUP(A21,ATIVO_PAI!A:H,2,0) -> MNO3P45 | C21: =VLOOKUP(A21,ATIVO_PAI!A:H,7,0) -> A | D21: =COUNTIFS(OCORRENCIAS!B:B,A21,OCORRENCIAS!F:F,"Aberta") -> 1 | E21: =COUNTIFS(SUBATIVOS!B:B,A21,SUBATIVOS!D:D,"Degradado") -> 0 | F21: =COUNTIFS(PNEUS!B:B,A21,PNEUS!G:G,"Condenado") -> 0 | G21: =IF(OR(C21="D",COUNTIFS(SUBATIVOS!B:B,A21,SUBATIVOS!D:D,"Inoperante")>0,F21>0),"Crítico",IF(OR(C21="C",D21>0,E21>0),"Atenção","OK")) -> Atenção
A23: ALERTAS — OCORRÊNCIAS ABERTAS
A24: Oco_ID | B24: Asset_ID | C24: Placa | D24: Tipo | E24: Descrição | F24: Gravidade | G24: Status
B25: =IF(A25="","",VLOOKUP(A25,OCORRENCIAS!A:B,2,0)) | C25: =IF(B25="","",VLOOKUP(B25,ATIVO_PAI!A:B,2,0)) | D25: =IF(A25="","",VLOOKUP(A25,OCORRENCIAS!A:C,3,0)) | E25: =IF(A25="","",VLOOKUP(A25,OCORRENCIAS!A:D,4,0)) | F25: =IF(A25="","",VLOOKUP(A25,OCORRENCIAS!A:E,5,0)) | G25: =IF(A25="","",VLOOKUP(A25,OCORRENCIAS!A:F,6,0))
B26: =IF(A26="","",VLOOKUP(A26,OCORRENCIAS!A:B,2,0)) | C26: =IF(B26="","",VLOOKUP(B26,ATIVO_PAI!A:B,2,0)) | D26: =IF(A26="","",VLOOKUP(A26,OCORRENCIAS!A:C,3,0)) | E26: =IF(A26="","",VLOOKUP(A26,OCORRENCIAS!A:D,4,0)) | F26: =IF(A26="","",VLOOKUP(A26,OCORRENCIAS!A:E,5,0)) | G26: =IF(A26="","",VLOOKUP(A26,OCORRENCIAS!A:F,6,0))
B27: =IF(A27="","",VLOOKUP(A27,OCORRENCIAS!A:B,2,0)) | C27: =IF(B27="","",VLOOKUP(B27,ATIVO_PAI!A:B,2,0)) | D27: =IF(A27="","",VLOOKUP(A27,OCORRENCIAS!A:C,3,0)) | E27: =IF(A27="","",VLOOKUP(A27,OCORRENCIAS!A:D,4,0)) | F27: =IF(A27="","",VLOOKUP(A27,OCORRENCIAS!A:E,5,0)) | G27: =IF(A27="","",VLOOKUP(A27,OCORRENCIAS!A:F,6,0))
B28: =IF(A28="","",VLOOKUP(A28,OCORRENCIAS!A:B,2,0)) | C28: =IF(B28="","",VLOOKUP(B28,ATIVO_PAI!A:B,2,0)) | D28: =IF(A28="","",VLOOKUP(A28,OCORRENCIAS!A:C,3,0)) | E28: =IF(A28="","",VLOOKUP(A28,OCORRENCIAS!A:D,4,0)) | F28: =IF(A28="","",VLOOKUP(A28,OCORRENCIAS!A:E,5,0)) | G28: =IF(A28="","",VLOOKUP(A28,OCORRENCIAS!A:F,6,0))
B29: =IF(A29="","",VLOOKUP(A29,OCORRENCIAS!A:B,2,0)) | C29: =IF(B29="","",VLOOKUP(B29,ATIVO_PAI!A:B,2,0)) | D29: =IF(A29="","",VLOOKUP(A29,OCORRENCIAS!A:C,3,0)) | E29: =IF(A29="","",VLOOKUP(A29,OCORRENCIAS!A:D,4,0)) | F29: =IF(A29="","",VLOOKUP(A29,OCORRENCIAS!A:E,5,0)) | G29: =IF(A29="","",VLOOKUP(A29,OCORRENCIAS!A:F,6,0))
B30: =IF(A30="","",VLOOKUP(A30,OCORRENCIAS!A:B,2,0)) | C30: =IF(B30="","",VLOOKUP(B30,ATIVO_PAI!A:B,2,0)) | D30: =IF(A30="","",VLOOKUP(A30,OCORRENCIAS!A:C,3,0)) | E30: =IF(A30="","",VLOOKUP(A30,OCORRENCIAS!A:D,4,0)) | F30: =IF(A30="","",VLOOKUP(A30,OCORRENCIAS!A:E,5,0)) | G30: =IF(A30="","",VLOOKUP(A30,OCORRENCIAS!A:F,6,0))
B31: =IF(A31="","",VLOOKUP(A31,OCORRENCIAS!A:B,2,0)) | C31: =IF(B31="","",VLOOKUP(B31,ATIVO_PAI!A:B,2,0)) | D31: =IF(A31="","",VLOOKUP(A31,OCORRENCIAS!A:C,3,0)) | E31: =IF(A31="","",VLOOKUP(A31,OCORRENCIAS!A:D,4,0)) | F31: =IF(A31="","",VLOOKUP(A31,OCORRENCIAS!A:E,5,0)) | G31: =IF(A31="","",VLOOKUP(A31,OCORRENCIAS!A:F,6,0))
B32: =IF(A32="","",VLOOKUP(A32,OCORRENCIAS!A:B,2,0)) | C32: =IF(B32="","",VLOOKUP(B32,ATIVO_PAI!A:B,2,0)) | D32: =IF(A32="","",VLOOKUP(A32,OCORRENCIAS!A:C,3,0)) | E32: =IF(A32="","",VLOOKUP(A32,OCORRENCIAS!A:D,4,0)) | F32: =IF(A32="","",VLOOKUP(A32,OCORRENCIAS!A:E,5,0)) | G32: =IF(A32="","",VLOOKUP(A32,OCORRENCIAS!A:F,6,0))
B33: =IF(A33="","",VLOOKUP(A33,OCORRENCIAS!A:B,2,0)) | C33: =IF(B33="","",VLOOKUP(B33,ATIVO_PAI!A:B,2,0)) | D33: =IF(A33="","",VLOOKUP(A33,OCORRENCIAS!A:C,3,0)) | E33: =IF(A33="","",VLOOKUP(A33,OCORRENCIAS!A:D,4,0)) | F33: =IF(A33="","",VLOOKUP(A33,OCORRENCIAS!A:E,5,0)) | G33: =IF(A33="","",VLOOKUP(A33,OCORRENCIAS!A:F,6,0))
B34: =IF(A34="","",VLOOKUP(A34,OCORRENCIAS!A:B,2,0)) | C34: =IF(B34="","",VLOOKUP(B34,ATIVO_PAI!A:B,2,0)) | D34: =IF(A34="","",VLOOKUP(A34,OCORRENCIAS!A:C,3,0)) | E34: =IF(A34="","",VLOOKUP(A34,OCORRENCIAS!A:D,4,0)) | F34: =IF(A34="","",VLOOKUP(A34,OCORRENCIAS!A:E,5,0)) | G34: =IF(A34="","",VLOOKUP(A34,OCORRENCIAS!A:F,6,0))

Sheet ATIVO_PAI
A1: Asset_ID | B1: Placa | C1: Tipo | D1: Proprio_Locado | E1: Locador | F1: Km/Horimetro | G1: Classificacao | H1: Data_Inspecao
A2: ATV-001 | B2: ABC1D23 | C2: Cavalo | D2: Locado | E2: Locadora X | F2: 152340 | G2: B | H2: 2026-09-28
A3: ATV-002 | B3: DEF4G56 | C3: Carreta | D3: Próprio | F3: 82300 | G3: A | H3: 2026-09-28
A4: ATV-003 | B4: GHI7J89 | C4: Van | D4: Locado | E4: Locadora Y | F4: 98750 | G4: C | H4: 2026-09-27
A5: ATV-004 | B5: JKL0M12 | C5: Gerador | D5: Próprio | F5: 4200 | G5: D | H5: 2026-09-26
A6: ATV-005 | B6: MNO3P45 | C6: Moto | D6: Próprio | F6: 18400 | G6: A | H6: 2026-09-25

Sheet SUBATIVOS
A1: Sub_ID | B1: Asset_ID | C1: Nome | D1: Estado | E1: Classificacao | F1: Acao | G1: Prioridade
A2: SUB-001 | B2: ATV-001 | C2: Motor | D2: Funcional | E2: A | F2: Nenhuma | G2: Baixa | H2: =IF(OR($B2="",$B2<>PASSAPORTE!$B$4),"",COUNTIF($B$2:$B2,PASSAPORTE!$B$4))
A3: SUB-002 | B3: ATV-001 | C3: Câmbio | D3: Funcional | E3: A | F3: Nenhuma | G3: Baixa | H3: =IF(OR($B3="",$B3<>PASSAPORTE!$B$4),"",COUNTIF($B$2:$B3,PASSAPORTE!$B$4))
A4: SUB-003 | B4: ATV-001 | C4: Freios | D4: Degradado | E4: B | F4: Trocar pastilhas | G4: Média | H4: =IF(OR($B4="",$B4<>PASSAPORTE!$B$4),"",COUNTIF($B$2:$B4,PASSAPORTE!$B$4))
A5: SUB-004 | B5: ATV-002 | C5: Motor | D5: Funcional | E5: A | F5: Nenhuma | G5: Baixa | H5: =IF(OR($B5="",$B5<>PASSAPORTE!$B$4),"",COUNTIF($B$2:$B5,PASSAPORTE!$B$4))
A6: SUB-005 | B6: ATV-002 | C6: Câmbio | D6: Funcional | E6: A | F6: Nenhuma | G6: Baixa | H6: =IF(OR($B6="",$B6<>PASSAPORTE!$B$4),"",COUNTIF($B$2:$B6,PASSAPORTE!$B$4))
A7: SUB-006 | B7: ATV-002 | C7: Suspensão | D7: Funcional | E7: A | F7: Nenhuma | G7: Baixa | H7: =IF(OR($B7="",$B7<>PASSAPORTE!$B$4),"",COUNTIF($B$2:$B7,PASSAPORTE!$B$4))
A8: SUB-007 | B8: ATV-003 | C8: Motor | D8: Degradado | E8: B | F8: Revisar injeção | G8: Média | H8: =IF(OR($B8="",$B8<>PASSAPORTE!$B$4),"",COUNTIF($B$2:$B8,PASSAPORTE!$B$4)) -> 1
A9: SUB-008 | B9: ATV-003 | C9: Freios | D9: Degradado | E9: C | F9: Trocar discos | G9: Alta | H9: =IF(OR($B9="",$B9<>PASSAPORTE!$B$4),"",COUNTIF($B$2:$B9,PASSAPORTE!$B$4)) -> 2
A10: SUB-009 | B10: ATV-003 | C10: Elétrica | D10: Funcional | E10: A | F10: Nenhuma | G10: Baixa | H10: =IF(OR($B10="",$B10<>PASSAPORTE!$B$4),"",COUNTIF($B$2:$B10,PASSAPORTE!$B$4)) -> 3
A11: SUB-010 | B11: ATV-004 | C11: Motor | D11: Inoperante | E11: D | F11: Diagnóstico urgente | G11: Alta | H11: =IF(OR($B11="",$B11<>PASSAPORTE!$B$4),"",COUNTIF($B$2:$B11,PASSAPORTE!$B$4))
A12: SUB-011 | B12: ATV-004 | C12: Bateria | D12: Inoperante | E12: D | F12: Substituir | G12: Alta | H12: =IF(OR($B12="",$B12<>PASSAPORTE!$B$4),"",COUNTIF($B$2:$B12,PASSAPORTE!$B$4))
A13: SUB-012 | B13: ATV-004 | C13: Alternador | D13: Degradado | E13: C | F13: Revisar | G13: Alta | H13: =IF(OR($B13="",$B13<>PASSAPORTE!$B$4),"",COUNTIF($B$2:$B13,PASSAPORTE!$B$4))
... A16: SUB-015 | B16: ATV-005 | C16: Pneus | D16: Funcional | E16: A | F16: Nenhuma | G16: Baixa | H16: =IF(OR($B16="",$B16<>PASSAPORTE!$B$4),"",COUNTIF($B$2:$B16,PASSAPORTE!$B$4))

Sheet PNEUS
A1: Pneu_ID | B1: Asset_ID | C1: Posicao | D1: Marca | E1: Medida | F1: Sulco | G1: Status
A2: PNE-001 | B2: ATV-001 | C2: 1E | D2: Michelin | E2: 295/80 | F2: 8 | G2: Instalado | H2: =IF(OR($B2="",$B2<>PASSAPORTE!$B$4),"",COUNTIF($B$2:$B2,PASSAPORTE!$B$4))
A3: PNE-002 | B3: ATV-001 | C3: 1D | D3: Michelin | E3: 295/80 | F3: 7 | G3: Instalado | H3: =IF(OR($B3="",$B3<>PASSAPORTE!$B$4),"",COUNTIF($B$2:$B3,PASSAPORTE!$B$4))
A4: PNE-003 | B4: ATV-001 | C4: 2E | D4: Michelin | E4: 295/80 | F4: 6 | G4: Instalado | H4: =IF(OR($B4="",$B4<>PASSAPORTE!$B$4),"",COUNTIF($B$2:$B4,PASSAPORTE!$B$4))
A5: PNE-004 | B5: ATV-001 | C5: 2D | D5: Michelin | E5: 295/80 | F5: 6 | G5: Instalado | H5: =IF(OR($B5="",$B5<>PASSAPORTE!$B$4),"",COUNTIF($B$2:$B5,PASSAPORTE!$B$4))
A6: PNE-005 | B6: ATV-001 | C6: 3E | D6: Bridgestone | E6: 295/80 | F6: 4 | G6: Instalado | H6: =IF(OR($B6="",$B6<>PASSAPORTE!$B$4),"",COUNTIF($B$2:$B6,PASSAPORTE!$B$4))
A7: PNE-006 | B7: ATV-001 | C7: 3D | D7: Bridgestone | E7: 295/80 | F7: 3 | G7: Instalado | H7: =IF(OR($B7="",$B7<>PASSAPORTE!$B$4),"",COUNTIF($B$2:$B7,PASSAPORTE!$B$4))
A8: PNE-007 | B8: ATV-002 | C8: 1E | D8: Pirelli | E8: 295/80 | F8: 9 | G8: Instalado | H8: =IF(OR($B8="",$B8<>PASSAPORTE!$B$4),"",COUNTIF($B$2:$B8,PASSAPORTE!$B$4))
A9: PNE-008 | B9: ATV-002 | C9: 1D | D9: Pirelli | E9: 295/80 | F9: 9 | G9: Instalado | H9: =IF(OR($B9="",$B9<>PASSAPORTE!$B$4),"",COUNTIF($B$2:$B9,PASSAPORTE!$B$4))
A10: PNE-009 | B10: ATV-002 | C10: 2E | D10: Pirelli | E10: 295/80 | F10: 8 | G10: Instalado | H10: =IF(OR($B10="",$B10<>PASSAPORTE!$B$4),"",COUNTIF($B$2:$B10,PASSAPORTE!$B$4))
A11: PNE-010 | B11: ATV-002 | C11: 2D | D11: Pirelli | E11: 295/80 | F11: 8 | G11: Instalado | H11: =IF(OR($B11="",$B11<>PASSAPORTE!$B$4),"",COUNTIF($B$2:$B11,PASSAPORTE!$B$4))
A12: PNE-011 | B12: ATV-003 | C12: 1E | D12: Goodyear | E12: 225/75 | F12: 6 | G12: Instalado | H12: =IF(OR($B12="",$B12<>PASSAPORTE!$B$4),"",COUNTIF($B$2:$B12,PASSAPORTE!$B$4)) -> 1
A13: PNE-012 | B13: ATV-003 | C13: 1D | D13: Goodyear | E13: 225/75 | F13: 5 | G13: Instalado | H13: =IF(OR($B13="",$B13<>PASSAPORTE!$B$4),"",COUNTIF($B$2:$B13,PASSAPORTE!$B$4)) -> 2
... A21: PNE-020 | B21: ATV-001 | C21: - | D21: Michelin | E21: 295/80 | F21: 9 | G21: Estoque | H21: =IF(OR($B21="",$B21<>PASSAPORTE!$B$4),"",COUNTIF($B$2:$B21,PASSAPORTE!$B$4))

Sheet OCORRENCIAS
A1: Oco_ID | B1: Asset_ID | C1: Tipo | D1: Descricao | E1: Gravidade | F1: Status | G1: Data
A2: OCO-001 | B2: ATV-001 | C2: Avaria | D2: Para-choque trincado | E2: Média | F2: Aberta | G2: 2026-09-28 | H2: =IF(OR($B2="",$B2<>PASSAPORTE!$B$4),"",COUNTIF($B$2:$B2,PASSAPORTE!$B$4))
A3: OCO-002 | B3: ATV-001 | C3: Pendência | D3: Documento CRLV vencendo | E3: Baixa | F3: Aberta | G3: 2026-09-28 | H3: =IF(OR($B3="",$B3<>PASSAPORTE!$B$4),"",COUNTIF($B$2:$B3,PASSAPORTE!$B$4))
A4: OCO-003 | B4: ATV-001 | C4: Falha | D4: Vazamento de óleo | E4: Alta | F4: Em Correção | G4: 2026-09-25 | H4: =IF(OR($B4="",$B4<>PASSAPORTE!$B$4),"",COUNTIF($B$2:$B4,PASSAPORTE!$B$4))
A5: OCO-004 | B5: ATV-002 | C5: Pendência | D5: Revisão dos 80.000 km | E5: Baixa | F5: Resolvida | G5: 2026-09-20 | H5: =IF(OR($B5="",$B5<>PASSAPORTE!$B$4),"",COUNTIF($B$2:$B5,PASSAPORTE!$B$4))
A6: OCO-005 | B6: ATV-002 | C6: Avaria | D6: Risco na porta lateral | E6: Baixa | F6: Resolvida | G6: 2026-09-15 | H6: =IF(OR($B6="",$B6<>PASSAPORTE!$B$4),"",COUNTIF($B$2:$B6,PASSAPORTE!$B$4))
A7: OCO-006 | B7: ATV-002 | C7: Falha | D7: Luz de injeção acesa | E7: Média | F7: Em Correção | G7: 2026-09-26 | H7: =IF(OR($B7="",$B7<>PASSAPORTE!$B$4),"",COUNTIF($B$2:$B7,PASSAPORTE!$B$4))
A8: OCO-007 | B8: ATV-003 | C8: Avaria | D8: Para-brisa trincado | E8: Alta | F8: Aberta | G8: 2026-09-27 | H8: =IF(OR($B8="",$B8<>PASSAPORTE!$B$4),"",COUNTIF($B$2:$B8,PASSAPORTE!$B$4)) -> 1
A9: OCO-008 | B9: ATV-003 | C9: Falha | D9: Freio traseiro fraco | E9: Alta | F9: Aberta | G9: 2026-09-27 | H9: =IF(OR($B9="",$B9<>PASSAPORTE!$B$4),"",COUNTIF($B$2:$B9,PASSAPORTE!$B$4)) -> 2
A10: OCO-009 | B10: ATV-003 | C10: Pendência | D10: Seguro a vencer | E10: Média | F10: Aberta | G10: 2026-09-24 | H10: =IF(OR($B10="",$B10<>PASSAPORTE!$B$4),"",COUNTIF($B$2:$B10,PASSAPORTE!$B$4)) -> 3
A11: OCO-010 | B11: ATV-003 | C11: Avaria | D11: Amassado lateral direita | E11: Baixa | F11: Resolvida | G11: 2026-09-10 | H11: =IF(OR($B11="",$B11<>PASSAPORTE!$B$4),"",COUNTIF($B$2:$B11,PASSAPORTE!$B$4)) -> 4
A12: OCO-011 | B12: ATV-004 | C12: Falha | D12: Não liga | E12: Crítica | F12: Aberta | G12: 2026-09-26 | H12: =IF(OR($B12="",$B12<>PASSAPORTE!$B$4),"",COUNTIF($B$2:$B12,PASSAPORTE!$B$4))
A13: OCO-012 | B13: ATV-004 | C13: Falha | D13: Bateria descarregando | E13: Crítica | F13: Em Correção | G13: 2026-09-26 | H13: =IF(OR($B13="",$B13<>PASSAPORTE!$B$4),"",COUNTIF($B$2:$B13,PASSAPORTE!$B$4))
... A21: OCO-020 | B21: ATV-003 | C21: Falha | D21: Ar-condicionado sem gelar | E21: Baixa | F21: Aberta | G21: 2026-09-28 | H21: =IF(OR($B21="",$B21<>PASSAPORTE!$B$4),"",COUNTIF($B$2:$B21,PASSAPORTE!$B$4)) -> 5

Sheet INSPECOES
A1: Insp_ID | B1: Asset_ID | C1: Data | D1: Inspecionado_Por | E1: Class_Antes | F1: Class_Depois | G1: Km_Horimetro | H1: Resumo
A2: INS-006 | B2: ATV-004 | C2: 2026-09-26 | D2: Kaká | E2: C | F2: D | G2: 4200 | H2: Motor travou; bloqueio técnico | I2: =IF(OR($B2="",$B2<>PASSAPORTE!$B$4),"",COUNTIF($B$2:$B2,PASSAPORTE!$B$4))
A3: INS-005 | B3: ATV-003 | C3: 2026-09-27 | D3: Kaká | E3: B | F3: C | G3: 98750 | H3: Freios e injeção degradaram | I3: =IF(OR($B3="",$B3<>PASSAPORTE!$B$4),"",COUNTIF($B$2:$B3,PASSAPORTE!$B$4)) -> 1
A4: INS-004 | B4: ATV-005 | C4: 2026-09-25 | D4: Kaká | E4: A | F4: A | G4: 18400 | H4: Sem alteração | I4: =IF(OR($B4="",$B4<>PASSAPORTE!$B$4),"",COUNTIF($B$2:$B4,PASSAPORTE!$B$4))
A5: INS-003 | B5: ATV-002 | C5: 2026-09-28 | D5: Kaká | E5: A | F5: A | G5: 82300 | H5: Sem alteração | I5: =IF(OR($B5="",$B5<>PASSAPORTE!$B$4),"",COUNTIF($B$2:$B5,PASSAPORTE!$B$4))
A6: INS-002 | B6: ATV-001 | C6: 2026-09-28 | D6: Kaká | E6: A | F6: B | G6: 152340 | H6: Freios degradados | I6: =IF(OR($B6="",$B6<>PASSAPORTE!$B$4),"",COUNTIF($B$2:$B6,PASSAPORTE!$B$4))
A7: INS-001 | B7: ATV-001 | C7: 2026-07-15 | D7: Kaká | E7: — | F7: A | G7: 148000 | H7: Inspeção inicial | I7: =IF(OR($B7="",$B7<>PASSAPORTE!$B$4),"",COUNTIF($B$2:$B7,PASSAPORTE!$B$4))

Sheet EVENTOS
A1: Evento_ID | B1: Data | C1: Asset_ID | D1: Tipo | E1: Ref_ID | F1: Descricao | G1: Antes | H1: Depois | I1: Responsavel
A2: EVE-008 | B2: 2026-09-28 | C2: ATV-001 | D2: Inspeção | E2: INS-002 | F2: Classificação A → B | G2: A | H2: B | I2: Kaká | J2: =IF(OR($B2="",$B2<>PASSAPORTE!$B$4),"",COUNTIF($B$2:$B2,PASSAPORTE!$B$4))
A3: EVE-007 | B3: 2026-09-28 | C3: ATV-001 | D3: Mudança Subativo | E3: SUB-003 | F3: Freios: Funcional → Degradado | G3: A | H3: B | I3: Kaká | J3: =IF(OR($B3="",$B3<>PASSAPORTE!$B$4),"",COUNTIF($B$2:$B3,PASSAPORTE!$B$4))
A4: EVE-006 | B4: 2026-09-28 | C4: ATV-001 | D4: Ocorrência Aberta | E4: OCO-019 | F4: Pneu dianteiro esvaziando | G4: — | H4: Aberta | I4: Kaká | J4: =IF(OR($B4="",$B4<>PASSAPORTE!$B$4),"",COUNTIF($B$2:$B4,PASSAPORTE!$B$4))
A5: EVE-005 | B5: 2026-09-27 | C5: ATV-003 | D5: Inspeção | E5: INS-005 | F5: Classificação B → C | G5: B | H5: C | I5: Kaká | J5: =IF(OR($B5="",$B5<>PASSAPORTE!$B$4),"",COUNTIF($B$2:$B5,PASSAPORTE!$B$4))
A6: EVE-004 | B6: 2026-09-26 | C6: ATV-004 | D6: Ativo Bloqueado | E6: INS-006 | F6: Classificação C → D | G6: C | H6: D | I6: Kaká | J6: =IF(OR($B6="",$B6<>PASSAPORTE!$B$4),"",COUNTIF($B$2:$B6,PASSAPORTE!$B$4))
A7: EVE-003 | B7: 2026-09-25 | C7: ATV-001 | D7: Ocorrência Aberta | E7: OCO-003 | F7: Vazamento de óleo | G7: — | H7: Aberta | I7: Kaká | J7: =IF(OR($B7="",$B7<>PASSAPORTE!$B$4),"",COUNTIF($B$2:$B7,PASSAPORTE!$B$4))
A8: EVE-002 | B8: 2026-09-20 | C8: ATV-002 | D8: Ocorrência Resolvida | E8: OCO-004 | F8: Revisão concluída | G8: Aberta | H8: Resolvida | I8: Estagiário | J8: =IF(OR($B8="",$B8<>PASSAPORTE!$B$4),"",COUNTIF($B$2:$B8,PASSAPORTE!$B$4))
A9: EVE-001 | B9: 2026-07-15 | C9: ATV-001 | D9: Inspeção | E9: INS-001 | F9: Inspeção inicial | G9: — | H9: A | I9: Kaká | J9: =IF(OR($B9="",$B9<>PASSAPORTE!$B$4),"",COUNTIF($B$2:$B9,PASSAPORTE!$B$4))

Sheet LEGENDA
A1: LEGENDA · GLOSSÁRIO E REGRAS
A3: 1. CLASSIFICAÇÃO DO ATIVO (A/B/C/D)
A4: A — APTO | B4: Verde | C4: Operacional, seguro, sem pendência relevante.
A5: B — APTO COM PENDÊNCIA | B5: Azul | C5: Pode operar, mas possui intervenção programável.
A6: C — CRÍTICO | B6: Laranja | C6: Risco significativo de indisponibilidade.
A7: D — INAPTO | B7: Vermelho | C7: Risco incompatível com operação; bloqueio técnico.
A9: 2. ESTADO DE SUBATIVO
A10: Funcional | B10: Verde | C10: Operando normalmente.
A11: Degradado | B11: Laranja | C11: Opera, mas com desgaste ou falha programável.
A12: Inoperante | B12: Vermelho | C12: Não opera; requer intervenção imediata.
A14: 3. STATUS DE PNEU
A15: Instalado | B15: Verde | C15: Em uso no veículo.
A16: Estoque | B16: Azul | C16: Disponível para uso.
A17: Condenado | B17: Vermelho | C17: Fora de uso; descarte ou recapagem.
A19: 4. STATUS DE OCORRÊNCIA
A20: Aberta | B20: Vermelho | C20: Registrada, sem tratativa iniciada.
A21: Em Correção | B21: Laranja | C21: Em tratativa.
A22: Resolvida | B22: Verde | C22: Finalizada.
A24: 5. GRAVIDADE DE OCORRÊNCIA
A25: Baixa | B25: Cinza | C25: Sem impacto imediato.
A26: Média | B26: Amarelo | C26: Atenção; pode evoluir.
A27: Alta | B27: Laranja | C27: Prioridade; impacto operacional.
A28: Crítica | B28: Vermelho | C28: Risco imediato; ação urgente.
A30: 6. REGRAS DE OURO
A31: • Estado atual SOBRESCREVE. Histórico sempre ADICIONA.
A32: • Nunca apague linhas de INSPECOES ou EVENTOS.
A33: • Toda mudança de classificação exige linha em INSPECOES e EVENTOS.
A34: • Toda mudança de subativo, pneu ou ocorrência gera linha em EVENTOS.
A35: • Antes de alterar, confira o ID do ativo. Erro de ID quebra as conexões.
A36: • Se algo parecer errado, verifique se há espaços extras nos IDs.
